Workbook

Sheet Jan
A1: END OF MONTH ACTIVITY TOTALS INTERDICTION January | N1: Drug Seizures
A2: NAME | B2: Hours Worked | C2: Drug Seizures | D2: Criminal Seizures | E2: Currency Seizures | F2: Training Hours | G2: Vehicle Searches | H2: Assist Narc-Ops | I2: Traffic Stops | J2: Warrant Arrests | K2: PC Arrests | L2: Agency Assist | M2: NAME | N2: Methamphetamine (g) | O2: Cocaine (g) | P2: Heroin (g) | Q2: Fentanyl (g) | R2: Marijuana (OZ) | S2: Promethazine/ Codeine (OZ) | T2: RX Pills (#)
A10: Jake Droddy | M10: Jake Droddy
A11: Week 1 | M11: Week 1
A12: Week 2 | M12: Week 2
A13: Week 3 | M13: Week 3
A14: Week 4 | M14: Week 4
A15: Week 5 | M15: Week 5
A16: Total | B16: =SUM(B11:B15) -> 0 | C16: =SUM(C11:C15) -> 0 | D16: =SUM(D11:D15) -> 0 | E16: =SUM(E11:E15) -> 0 | F16: =SUM(F11:F15) -> 0 | G16: =SUM(G11:G15) -> 0 | H16: =SUM(H11:H15) -> 0 | I16: =SUM(I11:I15) -> 0 | ... L16: =SUM(L11:L15) -> 0 | M16: TOTAL | N16: =SUM(N11:N15) -> 0 | O16: =SUM(O11:O15) -> 0 | P16: =SUM(P11:P15) -> 0 | Q16: =SUM(Q11:Q15) -> 0 | R16: =SUM(S11:S15) -> 0 | S16: =SUM(S11:S15) -> 0 | T16: =SUM(T11:T15) -> 0
A17: Brigitte Morse | M17: Brigitte Morse
A18: Week 1 | M18: Week 1
A19: Week 2 | M19: Week 2
A20: Week 3 | M20: Week 3
A21: Week 4 | M21: Week 4
A22: Week 5 | M22: Week 5
A23: Total | B23: =SUM(B18:B22) -> 0 | C23: =SUM(C18:C22) -> 0 | D23: =SUM(D18:D22) -> 0 | E23: =SUM(E18:E22) -> 0 | F23: =SUM(F18:F22) -> 0 | G23: =SUM(G18:G22) -> 0 | H23: =SUM(H18:H22) -> 0 | I23: =SUM(I18:I22) -> 0 | ... L23: =SUM(L18:L22) -> 0 | M23: TOTAL | N23: =SUM(N18:N22) -> 0 | O23: =SUM(O18:O22) -> 0 | P23: =SUM(P18:P22) -> 0 | Q23: =SUM(Q18:Q22) -> 0 | R23: =SUM(R18:R22) -> 0 | S23: =SUM(S18:S22) -> 0 | T23: =SUM(T18:T22) -> 0
A24: Interdiction Unit Total | B24: =SUM(B16,B23,) -> 0 | C24: =SUM(C16,C23) -> 0 | D24: =SUM(D16,D23) -> 0 | E24: =SUM(E16,E23) -> 0 | F24: =SUM(F16,F23) -> 0 | G24: =SUM(G16,G23) -> 0 | H24: =SUM(H16,H23) -> 0 | I24: =SUM(I16,I23) -> 0 | J24: =SUM(J16,J23) -> 0 | ... L24: =SUM(L16,L23) -> 0 | M24: Scott Weaver
B25: UNIFORM NARCOTICS DETECTIVE | M25: Week 1
A26: NAME | B26: Hours Worked | C26: Time Off | D26: K9 Deploy | E26: TNO Cases | F26: Training Hours | G26: Surv. Hours | H26: Patrol/Jail Cases | I26: Traffic Stops | J26: Warrant Arrests | K26: Agency Assist | L26: Supp. reports | M26: Week 2
A27: Scott Weaver | M27: Week 3
A28: Week 1 | M28: Week 4
A29: Week 2 | M29: Week 5
A30: Week 3 | M30: TOTAL | N30: =SUM(N25:N29) -> 0 | O30: =SUM(O25:O29) -> 0 | P30: =SUM(P25:P29) -> 0 | Q30: =SUM(Q25:Q29) -> 0 | R30: =SUM(R25:R29) -> 0 | S30: =SUM(S25:S29) -> 0 | T30: =SUM(T25:T29) -> 0
A31: Week 4 | M31: Brian Chowns
A32: Week 5 | M32: Week 1
A33: Total | B33: =SUM(B28:B32) -> 0 | C33: =SUM(C28:C32) -> 0 | D33: =SUM(D28:D32) -> 0 | E33: =SUM(E28:E32) -> 0 | F33: =SUM(F28:F32) -> 0 | G33: =SUM(G28:G32) -> 0 | H33: =SUM(H28:H32) -> 0 | I33: =SUM(I28:I32) -> 0 | ... L33: =SUM(L28:L32) -> 0 | M33: Week 2
A34: Brian Chowns | M34: Week 3
A35: Week 1 | M35: Week 4
A36: Week 2 | M36: Week 5
A37: Week 3 | M37: TOTAL | N37: =SUM(N32:N36) -> 0 | O37: =SUM(O32:O36) -> 0 | P37: =SUM(P32:P36) -> 0 | Q37: =SUM(Q32:Q36) -> 0 | R37: =SUM(R32:R36) -> 0 | S37: =SUM(S32:S36) -> 0 | T37: =SUM(T32:T36) -> 0
A38: Week 4 | M38: William Crain
A39: Week 5 | M39: Week 1
A40: Total | B40: =SUM(B35:B39) -> 0 | C40: =SUM(C35:C39) -> 0 | D40: =SUM(D35:D39) -> 0 | E40: =SUM(E35:E39) -> 0 | F40: =SUM(F35:F39) -> 0 | G40: =SUM(G35:G39) -> 0 | H40: =SUM(H35:H39) -> 0 | I40: =SUM(I35:I39) -> 0 | ... L40: =SUM(L35:L39) -> 0 | M40: Week 2
A41: William Crain | M41: Week 3
A42: Week 1 | M42: Week 4
A43: Week 2 | M43: Week 5
A44: Week 3 | M44: TOTAL | N44: =SUM(N39:N43) -> 0 | O44: =SUM(O39:O43) -> 0 | P44: =SUM(P39:P43) -> 0 | Q44: =SUM(Q39:Q43) -> 0 | R44: =SUM(R39:R43) -> 0 | S44: =SUM(S39:S43) -> 0 | T44: =SUM(T39:T43) -> 0
A45: Week 4 | M45: Tamara Spikes
A46: Week 5 | M46: Week 1
A47: Total | B47: =SUM(B42:B46) -> 0 | C47: =SUM(C42:C46) -> 0 | D47: =SUM(D42:D46) -> 0 | E47: =SUM(E42:E46) -> 0 | F47: =SUM(F42:F46) -> 0 | G47: =SUM(G42:G46) -> 0 | H47: =SUM(H42:H46) -> 0 | I47: =SUM(I42:I46) -> 0 | ... L47: =SUM(L42:L46) -> 0 | M47: Week 2
...

Sheet Feb
A1: END OF MONTH ACTIVITY TOTALS INTERDICTION February | N1: Drug Seizures
A2: NAME | B2: Hours Worked | C2: Drug Seizures | D2: Criminal Seizures | E2: Currency Seizures | F2: Training Hours | G2: Vehicle Searches | H2: Assist Narc-Ops | I2: Traffic Stops | J2: Warrant Arrests | K2: PC Arrests | L2: Agency Assist | M2: NAME | N2: Methamphetamine (g) | O2: Cocaine (g) | P2: Heroin (g) | Q2: Fentanyl (g) | R2: Marijuana (OZ) | S2: Promethazine/ Codeine (OZ) | T2: RX Pills (#)
A10: Jake Droddy | M10: Jake Droddy
A11: Week 1 | M11: Week 1
A12: Week 2 | M12: Week 2
A13: Week 3 | M13: Week 3
A14: Week 4 | M14: Week 4
A15: Week 5 | M15: Week 5
A16: Total | B16: =SUM(B11:B15) -> 0 | C16: =SUM(C11:C15) -> 0 | D16: =SUM(D11:D15) -> 0 | E16: =SUM(E11:E15) -> 0 | F16: =SUM(F11:F15) -> 0 | G16: =SUM(G11:G15) -> 0 | H16: =SUM(H11:H15) -> 0 | I16: =SUM(I11:I15) -> 0 | ... L16: =SUM(L11:L15) -> 0 | M16: TOTAL | N16: =SUM(N11:N15) -> 0 | O16: =SUM(O11:O15) -> 0 | P16: =SUM(P11:P15) -> 0 | Q16: =SUM(Q11:Q15) -> 0 | R16: =SUM(S11:S15) -> 0 | S16: =SUM(S11:S15) -> 0 | T16: =SUM(T11:T15) -> 0
A17: Brigitte Morse | M17: Brigitte Morse
A18: Week 1 | M18: Week 1
A19: Week 2 | M19: Week 2
A20: Week 3 | M20: Week 3
A21: Week 4 | M21: Week 4
A22: Week 5 | M22: Week 5
A23: Total | B23: =SUM(B18:B22) -> 0 | C23: =SUM(C18:C22) -> 0 | D23: =SUM(D18:D22) -> 0 | E23: =SUM(E18:E22) -> 0 | F23: =SUM(F18:F22) -> 0 | G23: =SUM(G18:G22) -> 0 | H23: =SUM(H18:H22) -> 0 | I23: =SUM(I18:I22) -> 0 | ... L23: =SUM(L18:L22) -> 0 | M23: TOTAL | N23: =SUM(N18:N22) -> 0 | O23: =SUM(O18:O22) -> 0 | P23: =SUM(P18:P22) -> 0 | Q23: =SUM(Q18:Q22) -> 0 | R23: =SUM(R18:R22) -> 0 | S23: =SUM(S18:S22) -> 0 | T23: =SUM(T18:T22) -> 0
A24: Interdiction Unit Total | B24: =SUM(B16,B23,) -> 0 | C24: =SUM(C16,C23) -> 0 | D24: =SUM(D16,D23) -> 0 | E24: =SUM(E16,E23) -> 0 | F24: =SUM(F16,F23) -> 0 | G24: =SUM(G16,G23) -> 0 | H24: =SUM(H16,H23) -> 0 | I24: =SUM(I16,I23) -> 0 | J24: =SUM(J16,J23) -> 0 | ... L24: =SUM(L16,L23) -> 0 | M24: Scott Weaver
B25: UNIFORM NARCOTICS DETECTIVE | M25: Week 1
A26: NAME | B26: Hours Worked | C26: Time Off | D26: K9 Deploy | E26: TNO Cases | F26: Training Hours | G26: Surv. Hours | H26: Patrol/Jail Cases | I26: Traffic Stops | J26: Warrant Arrests | K26: Agency Assist | L26: Supp. reports | M26: Week 2
A27: Scott Weaver | M27: Week 3
A28: Week 1 | M28: Week 4
A29: Week 2 | M29: Week 5
A30: Week 3 | M30: TOTAL | N30: =SUM(N25:N29) -> 0 | O30: =SUM(O25:O29) -> 0 | P30: =SUM(P25:P29) -> 0 | Q30: =SUM(Q25:Q29) -> 0 | R30: =SUM(R25:R29) -> 0 | S30: =SUM(S25:S29) -> 0 | T30: =SUM(T25:T29) -> 0
A31: Week 4 | M31: Brian Chowns
A32: Week 5 | M32: Week 1
A33: Total | B33: =SUM(B28:B32) -> 0 | C33: =SUM(C28:C32) -> 0 | D33: =SUM(D28:D32) -> 0 | E33: =SUM(E28:E32) -> 0 | F33: =SUM(F28:F32) -> 0 | G33: =SUM(G28:G32) -> 0 | H33: =SUM(H28:H32) -> 0 | I33: =SUM(I28:I32) -> 0 | ... L33: =SUM(L28:L32) -> 0 | M33: Week 2
A34: Brian Chowns | M34: Week 3
A35: Week 1 | M35: Week 4
A36: Week 2 | M36: Week 5
A37: Week 3 | M37: TOTAL | N37: =SUM(N32:N36) -> 0 | O37: =SUM(O32:O36) -> 0 | P37: =SUM(P32:P36) -> 0 | Q37: =SUM(Q32:Q36) -> 0 | R37: =SUM(R32:R36) -> 0 | S37: =SUM(S32:S36) -> 0 | T37: =SUM(T32:T36) -> 0
A38: Week 4 | M38: William Crain
A39: Week 5 | M39: Week 1
A40: Total | B40: =SUM(B35:B39) -> 0 | C40: =SUM(C35:C39) -> 0 | D40: =SUM(D35:D39) -> 0 | E40: =SUM(E35:E39) -> 0 | F40: =SUM(F35:F39) -> 0 | G40: =SUM(G35:G39) -> 0 | H40: =SUM(H35:H39) -> 0 | I40: =SUM(I35:I39) -> 0 | ... L40: =SUM(L35:L39) -> 0 | M40: Week 2
A41: William Crain | M41: Week 3
A42: Week 1 | M42: Week 4
A43: Week 2 | M43: Week 5
A44: Week 3 | M44: TOTAL | N44: =SUM(N39:N43) -> 0 | O44: =SUM(O39:O43) -> 0 | P44: =SUM(P39:P43) -> 0 | Q44: =SUM(Q39:Q43) -> 0 | R44: =SUM(R39:R43) -> 0 | S44: =SUM(S39:S43) -> 0 | T44: =SUM(T39:T43) -> 0
A45: Week 4 | M45: Tamara Spikes
A46: Week 5 | M46: Week 1
A47: Total | B47: =SUM(B42:B46) -> 0 | C47: =SUM(C42:C46) -> 0 | D47: =SUM(D42:D46) -> 0 | E47: =SUM(E42:E46) -> 0 | F47: =SUM(F42:F46) -> 0 | G47: =SUM(G42:G46) -> 0 | H47: =SUM(H42:H46) -> 0 | I47: =SUM(I42:I46) -> 0 | ... L47: =SUM(L42:L46) -> 0 | M47: Week 2
...

Sheet Mar
A1: END OF MONTH ACTIVITY TOTALS INTERDICTION March | N1: Drug Seizures
A2: NAME | B2: Hours Worked | C2: Drug Seizures | D2: Criminal Seizures | E2: Currency Seizures | F2: Training Hours | G2: Vehicle Searches | H2: Assist Narc-Ops | I2: Traffic Stops | J2: Warrant Arrests | K2: PC Arrests | L2: Agency Assist | M2: NAME | N2: Methamphetamine (g) | O2: Cocaine (g) | P2: Heroin (g) | Q2: Fentanyl (g) | R2: Marijuana (OZ) | S2: Promethazine/ Codeine (OZ) | T2: RX Pills (#)
A10: Jake Droddy | M10: Jake Droddy
A11: Week 1 | M11: Week 1
A12: Week 2 | M12: Week 2
A13: Week 3 | M13: Week 3
A14: Week 4 | M14: Week 4
A15: Week 5 | M15: Week 5
A16: Total | B16: =SUM(B11:B15) -> 0 | C16: =SUM(C11:C15) -> 0 | D16: =SUM(D11:D15) -> 0 | E16: =SUM(E11:E15) -> 0 | F16: =SUM(F11:F15) -> 0 | G16: =SUM(G11:G15) -> 0 | H16: =SUM(H11:H15) -> 0 | I16: =SUM(I11:I15) -> 0 | ... L16: =SUM(L11:L15) -> 0 | M16: TOTAL | N16: =SUM(N11:N15) -> 0 | O16: =SUM(O11:O15) -> 0 | P16: =SUM(P11:P15) -> 0 | Q16: =SUM(Q11:Q15) -> 0 | R16: =SUM(S11:S15) -> 0 | S16: =SUM(S11:S15) -> 0 | T16: =SUM(T11:T15) -> 0
A17: Brigitte Morse | M17: Brigitte Morse
A18: Week 1 | M18: Week 1
A19: Week 2 | M19: Week 2
A20: Week 3 | M20: Week 3
A21: Week 4 | M21: Week 4
A22: Week 5 | M22: Week 5
A23: Total | B23: =SUM(B18:B22) -> 0 | C23: =SUM(C18:C22) -> 0 | D23: =SUM(D18:D22) -> 0 | E23: =SUM(E18:E22) -> 0 | F23: =SUM(F18:F22) -> 0 | G23: =SUM(G18:G22) -> 0 | H23: =SUM(H18:H22) -> 0 | I23: =SUM(I18:I22) -> 0 | ... L23: =SUM(L18:L22) -> 0 | M23: TOTAL | N23: =SUM(N18:N22) -> 0 | O23: =SUM(O18:O22) -> 0 | P23: =SUM(P18:P22) -> 0 | Q23: =SUM(Q18:Q22) -> 0 | R23: =SUM(R18:R22) -> 0 | S23: =SUM(S18:S22) -> 0 | T23: =SUM(T18:T22) -> 0
A24: Interdiction Unit Total | B24: =SUM(B16,B23,) -> 0 | C24: =SUM(C16,C23) -> 0 | D24: =SUM(D16,D23) -> 0 | E24: =SUM(E16,E23) -> 0 | F24: =SUM(F16,F23) -> 0 | G24: =SUM(G16,G23) -> 0 | H24: =SUM(H16,H23) -> 0 | I24: =SUM(I16,I23) -> 0 | J24: =SUM(J16,J23) -> 0 | ... L24: =SUM(L16,L23) -> 0 | M24: Scott Weaver
B25: UNIFORM NARCOTICS DETECTIVE | M25: Week 1
A26: NAME | B26: Hours Worked | C26: Time Off | D26: K9 Deploy | E26: TNO Cases | F26: Training Hours | G26: Surv. Hours | H26: Patrol/Jail Cases | I26: Traffic Stops | J26: Warrant Arrests | K26: Agency Assist | L26: Supp. reports | M26: Week 2
A27: Scott Weaver | M27: Week 3
A28: Week 1 | M28: Week 4
A29: Week 2 | M29: Week 5
A30: Week 3 | M30: TOTAL | N30: =SUM(N25:N29) -> 0 | O30: =SUM(O25:O29) -> 0 | P30: =SUM(P25:P29) -> 0 | Q30: =SUM(Q25:Q29) -> 0 | R30: =SUM(R25:R29) -> 0 | S30: =SUM(S25:S29) -> 0 | T30: =SUM(T25:T29) -> 0
A31: Week 4 | M31: Brian Chowns
A32: Week 5 | M32: Week 1
A33: Total | B33: =SUM(B28:B32) -> 0 | C33: =SUM(C28:C32) -> 0 | D33: =SUM(D28:D32) -> 0 | E33: =SUM(E28:E32) -> 0 | F33: =SUM(F28:F32) -> 0 | G33: =SUM(G28:G32) -> 0 | H33: =SUM(H28:H32) -> 0 | I33: =SUM(I28:I32) -> 0 | ... L33: =SUM(L28:L32) -> 0 | M33: Week 2
A34: Brian Chowns | M34: Week 3
A35: Week 1 | M35: Week 4
A36: Week 2 | M36: Week 5
A37: Week 3 | M37: TOTAL | N37: =SUM(N32:N36) -> 0 | O37: =SUM(O32:O36) -> 0 | P37: =SUM(P32:P36) -> 0 | Q37: =SUM(Q32:Q36) -> 0 | R37: =SUM(R32:R36) -> 0 | S37: =SUM(S32:S36) -> 0 | T37: =SUM(T32:T36) -> 0
A38: Week 4 | M38: William Crain
A39: Week 5 | M39: Week 1
A40: Total | B40: =SUM(B35:B39) -> 0 | C40: =SUM(C35:C39) -> 0 | D40: =SUM(D35:D39) -> 0 | E40: =SUM(E35:E39) -> 0 | F40: =SUM(F35:F39) -> 0 | G40: =SUM(G35:G39) -> 0 | H40: =SUM(H35:H39) -> 0 | I40: =SUM(I35:I39) -> 0 | ... L40: =SUM(L35:L39) -> 0 | M40: Week 2
A41: William Crain | M41: Week 3
A42: Week 1 | M42: Week 4
A43: Week 2 | M43: Week 5
A44: Week 3 | M44: TOTAL | N44: =SUM(N39:N43) -> 0 | O44: =SUM(O39:O43) -> 0 | P44: =SUM(P39:P43) -> 0 | Q44: =SUM(Q39:Q43) -> 0 | R44: =SUM(R39:R43) -> 0 | S44: =SUM(S39:S43) -> 0 | T44: =SUM(T39:T43) -> 0
A45: Week 4 | M45: Tamara Spikes
A46: Week 5 | M46: Week 1
A47: Total | B47: =SUM(B42:B46) -> 0 | C47: =SUM(C42:C46) -> 0 | D47: =SUM(D42:D46) -> 0 | E47: =SUM(E42:E46) -> 0 | F47: =SUM(F42:F46) -> 0 | G47: =SUM(G42:G46) -> 0 | H47: =SUM(H42:H46) -> 0 | I47: =SUM(I42:I46) -> 0 | ... L47: =SUM(L42:L46) -> 0 | M47: Week 2
...

Sheet Apr
A1: END OF MONTH ACTIVITY TOTALS INTERDICTION April | N1: Drug Seizures
A2: NAME | B2: Hours Worked | C2: Drug Seizures | D2: Criminal Seizures | E2: Currency Seizures | F2: Training Hours | G2: Vehicle Searches | H2: Assist Narc-Ops | I2: Traffic Stops | J2: Warrant Arrests | K2: PC Arrests | L2: Agency Assist | M2: NAME | N2: Methamphetamine (g) | O2: Cocaine (g) | P2: Heroin (g) | Q2: Fentanyl (g) | R2: Marijuana (OZ) | S2: Promethazine/ Codeine (OZ) | T2: RX Pills (#)
A10: Jake Droddy | M10: Jake Droddy
A11: Week 1 | M11: Week 1
A12: Week 2 | M12: Week 2
A13: Week 3 | M13: Week 3
A14: Week 4 | M14: Week 4
A15: Week 5 | M15: Week 5
A16: Total | B16: =SUM(B11:B15) -> 0 | C16: =SUM(C11:C15) -> 0 | D16: =SUM(D11:D15) -> 0 | E16: =SUM(E11:E15) -> 0 | F16: =SUM(F11:F15) -> 0 | G16: =SUM(G11:G15) -> 0 | H16: =SUM(H11:H15) -> 0 | I16: =SUM(I11:I15) -> 0 | ... L16: =SUM(L11:L15) -> 0 | M16: TOTAL | N16: =SUM(N11:N15) -> 0 | O16: =SUM(O11:O15) -> 0 | P16: =SUM(P11:P15) -> 0 | Q16: =SUM(Q11:Q15) -> 0 | R16: =SUM(S11:S15) -> 0 | S16: =SUM(S11:S15) -> 0 | T16: =SUM(T11:T15) -> 0
A17: Brigitte Morse | M17: Brigitte Morse
A18: Week 1 | M18: Week 1
A19: Week 2 | M19: Week 2
A20: Week 3 | M20: Week 3
A21: Week 4 | M21: Week 4
A22: Week 5 | M22: Week 5
A23: Total | B23: =SUM(B18:B22) -> 0 | C23: =SUM(C18:C22) -> 0 | D23: =SUM(D18:D22) -> 0 | E23: =SUM(E18:E22) -> 0 | F23: =SUM(F18:F22) -> 0 | G23: =SUM(G18:G22) -> 0 | H23: =SUM(H18:H22) -> 0 | I23: =SUM(I18:I22) -> 0 | ... L23: =SUM(L18:L22) -> 0 | M23: TOTAL | N23: =SUM(N18:N22) -> 0 | O23: =SUM(O18:O22) -> 0 | P23: =SUM(P18:P22) -> 0 | Q23: =SUM(Q18:Q22) -> 0 | R23: =SUM(R18:R22) -> 0 | S23: =SUM(S18:S22) -> 0 | T23: =SUM(T18:T22) -> 0
A24: Interdiction Unit Total | B24: =SUM(B16,B23,) -> 0 | C24: =SUM(C16,C23) -> 0 | D24: =SUM(D16,D23) -> 0 | E24: =SUM(E16,E23) -> 0 | F24: =SUM(F16,F23) -> 0 | G24: =SUM(G16,G23) -> 0 | H24: =SUM(H16,H23) -> 0 | I24: =SUM(I16,I23) -> 0 | J24: =SUM(J16,J23) -> 0 | ... L24: =SUM(L16,L23) -> 0 | M24: Scott Weaver
B25: UNIFORM NARCOTICS DETECTIVE | M25: Week 1
A26: NAME | B26: Hours Worked | C26: Time Off | D26: K9 Deploy | E26: TNO Cases | F26: Training Hours | G26: Surv. Hours | H26: Patrol/Jail Cases | I26: Traffic Stops | J26: Warrant Arrests | K26: Agency Assist | L26: Supp. reports | M26: Week 2
A27: Scott Weaver | M27: Week 3
A28: Week 1 | M28: Week 4
A29: Week 2 | M29: Week 5
A30: Week 3 | M30: TOTAL | N30: =SUM(N25:N29) -> 0 | O30: =SUM(O25:O29) -> 0 | P30: =SUM(P25:P29) -> 0 | Q30: =SUM(Q25:Q29) -> 0 | R30: =SUM(R25:R29) -> 0 | S30: =SUM(S25:S29) -> 0 | T30: =SUM(T25:T29) -> 0
A31: Week 4 | M31: Brian Chowns
A32: Week 5 | M32: Week 1
A33: Total | B33: =SUM(B28:B32) -> 0 | C33: =SUM(C28:C32) -> 0 | D33: =SUM(D28:D32) -> 0 | E33: =SUM(E28:E32) -> 0 | F33: =SUM(F28:F32) -> 0 | G33: =SUM(G28:G32) -> 0 | H33: =SUM(H28:H32) -> 0 | I33: =SUM(I28:I32) -> 0 | ... L33: =SUM(L28:L32) -> 0 | M33: Week 2
A34: Brian Chowns | M34: Week 3
A35: Week 1 | M35: Week 4
A36: Week 2 | M36: Week 5
A37: Week 3 | M37: TOTAL | N37: =SUM(N32:N36) -> 0 | O37: =SUM(O32:O36) -> 0 | P37: =SUM(P32:P36) -> 0 | Q37: =SUM(Q32:Q36) -> 0 | R37: =SUM(R32:R36) -> 0 | S37: =SUM(S32:S36) -> 0 | T37: =SUM(T32:T36) -> 0
A38: Week 4 | M38: William Crain
A39: Week 5 | M39: Week 1
A40: Total | B40: =SUM(B35:B39) -> 0 | C40: =SUM(C35:C39) -> 0 | D40: =SUM(D35:D39) -> 0 | E40: =SUM(E35:E39) -> 0 | F40: =SUM(F35:F39) -> 0 | G40: =SUM(G35:G39) -> 0 | H40: =SUM(H35:H39) -> 0 | I40: =SUM(I35:I39) -> 0 | ... L40: =SUM(L35:L39) -> 0 | M40: Week 2
A41: William Crain | M41: Week 3
A42: Week 1 | M42: Week 4
A43: Week 2 | M43: Week 5
A44: Week 3 | M44: TOTAL | N44: =SUM(N39:N43) -> 0 | O44: =SUM(O39:O43) -> 0 | P44: =SUM(P39:P43) -> 0 | Q44: =SUM(Q39:Q43) -> 0 | R44: =SUM(R39:R43) -> 0 | S44: =SUM(S39:S43) -> 0 | T44: =SUM(T39:T43) -> 0
A45: Week 4 | M45: Tamara Spikes
A46: Week 5 | M46: Week 1
A47: Total | B47: =SUM(B42:B46) -> 0 | C47: =SUM(C42:C46) -> 0 | D47: =SUM(D42:D46) -> 0 | E47: =SUM(E42:E46) -> 0 | F47: =SUM(F42:F46) -> 0 | G47: =SUM(G42:G46) -> 0 | H47: =SUM(H42:H46) -> 0 | I47: =SUM(I42:I46) -> 0 | ... L47: =SUM(L42:L46) -> 0 | M47: Week 2
...

Sheet May
A1: END OF MONTH ACTIVITY TOTALS INTERDICTION May | N1: Drug Seizures
A2: NAME | B2: Hours Worked | C2: Drug Seizures | D2: Criminal Seizures | E2: Currency Seizures | F2: Training Hours | G2: Vehicle Searches | H2: Assist Narc-Ops | I2: Traffic Stops | J2: Warrant Arrests | K2: PC Arrests | L2: Agency Assist | M2: NAME | N2: Methamphetamine (g) | O2: Cocaine (g) | P2: Heroin (g) | Q2: Fentanyl (g) | R2: Marijuana (OZ) | S2: Promethazine/ Codeine (OZ) | T2: RX Pills (#)
A10: Jake Droddy | M10: Jake Droddy
A11: Week 1 | M11: Week 1
A12: Week 2 | M12: Week 2
A13: Week 3 | M13: Week 3
A14: Week 4 | M14: Week 4
A15: Week 5 | M15: Week 5
A16: Total | B16: =SUM(B11:B15) -> 0 | C16: =SUM(C11:C15) -> 0 | D16: =SUM(D11:D15) -> 0 | E16: =SUM(E11:E15) -> 0 | F16: =SUM(F11:F15) -> 0 | G16: =SUM(G11:G15) -> 0 | H16: =SUM(H11:H15) -> 0 | I16: =SUM(I11:I15) -> 0 | ... L16: =SUM(L11:L15) -> 0 | M16: TOTAL | N16: =SUM(N11:N15) -> 0 | O16: =SUM(O11:O15) -> 0 | P16: =SUM(P11:P15) -> 0 | Q16: =SUM(Q11:Q15) -> 0 | R16: =SUM(S11:S15) -> 0 | S16: =SUM(S11:S15) -> 0 | T16: =SUM(T11:T15) -> 0
A17: Brigitte Morse | M17: Brigitte Morse
A18: Week 1 | M18: Week 1
A19: Week 2 | M19: Week 2
A20: Week 3 | M20: Week 3
A21: Week 4 | M21: Week 4
A22: Week 5 | M22: Week 5
A23: Total | B23: =SUM(B18:B22) -> 0 | C23: =SUM(C18:C22) -> 0 | D23: =SUM(D18:D22) -> 0 | E23: =SUM(E18:E22) -> 0 | F23: =SUM(F18:F22) -> 0 | G23: =SUM(G18:G22) -> 0 | H23: =SUM(H18:H22) -> 0 | I23: =SUM(I18:I22) -> 0 | ... L23: =SUM(L18:L22) -> 0 | M23: TOTAL | N23: =SUM(N18:N22) -> 0 | O23: =SUM(O18:O22) -> 0 | P23: =SUM(P18:P22) -> 0 | Q23: =SUM(Q18:Q22) -> 0 | R23: =SUM(R18:R22) -> 0 | S23: =SUM(S18:S22) -> 0 | T23: =SUM(T18:T22) -> 0
A24: Interdiction Unit Total | B24: =SUM(B16,B23,) -> 0 | C24: =SUM(C16,C23) -> 0 | D24: =SUM(D16,D23) -> 0 | E24: =SUM(E16,E23) -> 0 | F24: =SUM(F16,F23) -> 0 | G24: =SUM(G16,G23) -> 0 | H24: =SUM(H16,H23) -> 0 | I24: =SUM(I16,I23) -> 0 | J24: =SUM(J16,J23) -> 0 | ... L24: =SUM(L16,L23) -> 0 | M24: Scott Weaver
B25: UNIFORM NARCOTICS DETECTIVE | M25: Week 1
A26: NAME | B26: Hours Worked | C26: Time Off | D26: K9 Deploy | E26: TNO Cases | F26: Training Hours | G26: Surv. Hours | H26: Patrol/Jail Cases | I26: Traffic Stops | J26: Warrant Arrests | K26: Agency Assist | L26: Supp. reports | M26: Week 2
A27: Scott Weaver | M27: Week 3
A28: Week 1 | M28: Week 4
A29: Week 2 | M29: Week 5
A30: Week 3 | M30: TOTAL | N30: =SUM(N25:N29) -> 0 | O30: =SUM(O25:O29) -> 0 | P30: =SUM(P25:P29) -> 0 | Q30: =SUM(Q25:Q29) -> 0 | R30: =SUM(R25:R29) -> 0 | S30: =SUM(S25:S29) -> 0 | T30: =SUM(T25:T29) -> 0
A31: Week 4 | M31: Brian Chowns
A32: Week 5 | M32: Week 1
A33: Total | B33: =SUM(B28:B32) -> 0 | C33: =SUM(C28:C32) -> 0 | D33: =SUM(D28:D32) -> 0 | E33: =SUM(E28:E32) -> 0 | F33: =SUM(F28:F32) -> 0 | G33: =SUM(G28:G32) -> 0 | H33: =SUM(H28:H32) -> 0 | I33: =SUM(I28:I32) -> 0 | ... L33: =SUM(L28:L32) -> 0 | M33: Week 2
A34: Brian Chowns | M34: Week 3
A35: Week 1 | M35: Week 4
A36: Week 2 | M36: Week 5
A37: Week 3 | M37: TOTAL | N37: =SUM(N32:N36) -> 0 | O37: =SUM(O32:O36) -> 0 | P37: =SUM(P32:P36) -> 0 | Q37: =SUM(Q32:Q36) -> 0 | R37: =SUM(R32:R36) -> 0 | S37: =SUM(S32:S36) -> 0 | T37: =SUM(T32:T36) -> 0
A38: Week 4 | M38: William Crain
A39: Week 5 | M39: Week 1
A40: Total | B40: =SUM(B35:B39) -> 0 | C40: =SUM(C35:C39) -> 0 | D40: =SUM(D35:D39) -> 0 | E40: =SUM(E35:E39) -> 0 | F40: =SUM(F35:F39) -> 0 | G40: =SUM(G35:G39) -> 0 | H40: =SUM(H35:H39) -> 0 | I40: =SUM(I35:I39) -> 0 | ... L40: =SUM(L35:L39) -> 0 | M40: Week 2
A41: William Crain | M41: Week 3
A42: Week 1 | M42: Week 4
A43: Week 2 | M43: Week 5
A44: Week 3 | M44: TOTAL | N44: =SUM(N39:N43) -> 0 | O44: =SUM(O39:O43) -> 0 | P44: =SUM(P39:P43) -> 0 | Q44: =SUM(Q39:Q43) -> 0 | R44: =SUM(R39:R43) -> 0 | S44: =SUM(S39:S43) -> 0 | T44: =SUM(T39:T43) -> 0
A45: Week 4 | M45: Tamara Spikes
A46: Week 5 | M46: Week 1
A47: Total | B47: =SUM(B42:B46) -> 0 | C47: =SUM(C42:C46) -> 0 | D47: =SUM(D42:D46) -> 0 | E47: =SUM(E42:E46) -> 0 | F47: =SUM(F42:F46) -> 0 | G47: =SUM(G42:G46) -> 0 | H47: =SUM(H42:H46) -> 0 | I47: =SUM(I42:I46) -> 0 | ... L47: =SUM(L42:L46) -> 0 | M47: Week 2
...

Sheet Jun
A1: END OF MONTH ACTIVITY TOTALS INTERDICTION June | N1: Drug Seizures
A2: NAME | B2: Hours Worked | C2: Drug Seizures | D2: Criminal Seizures | E2: Currency Seizures | F2: Training Hours | G2: Vehicle Searches | H2: Assist Narc-Ops | I2: Traffic Stops | J2: Warrant Arrests | K2: PC Arrests | L2: Agency Assist | M2: NAME | N2: Methamphetamine (g) | O2: Cocaine (g) | P2: Heroin (g) | Q2: Fentanyl (g) | R2: Marijuana (OZ) | S2: Promethazine/ Codeine (OZ) | T2: RX Pills (#)
A10: Jake Droddy | M10: Jake Droddy
A11: Week 1 | M11: Week 1
A12: Week 2 | M12: Week 2
A13: Week 3 | M13: Week 3
A14: Week 4 | M14: Week 4
A15: Week 5 | M15: Week 5
A16: Total | B16: =SUM(B11:B15) -> 0 | C16: =SUM(C11:C15) -> 0 | D16: =SUM(D11:D15) -> 0 | E16: =SUM(E11:E15) -> 0 | F16: =SUM(F11:F15) -> 0 | G16: =SUM(G11:G15) -> 0 | H16: =SUM(H11:H15) -> 0 | I16: =SUM(I11:I15) -> 0 | ... L16: =SUM(L11:L15) -> 0 | M16: TOTAL | N16: =SUM(N11:N15) -> 0 | O16: =SUM(O11:O15) -> 0 | P16: =SUM(P11:P15) -> 0 | Q16: =SUM(Q11:Q15) -> 0 | R16: =SUM(S11:S15) -> 0 | S16: =SUM(S11:S15) -> 0 | T16: =SUM(T11:T15) -> 0
A17: Brigitte Morse | M17: Brigitte Morse
A18: Week 1 | M18: Week 1
A19: Week 2 | M19: Week 2
A20: Week 3 | M20: Week 3
A21: Week 4 | M21: Week 4
A22: Week 5 | M22: Week 5
A23: Total | B23: =SUM(B18:B22) -> 0 | C23: =SUM(C18:C22) -> 0 | D23: =SUM(D18:D22) -> 0 | E23: =SUM(E18:E22) -> 0 | F23: =SUM(F18:F22) -> 0 | G23: =SUM(G18:G22) -> 0 | H23: =SUM(H18:H22) -> 0 | I23: =SUM(I18:I22) -> 0 | ... L23: =SUM(L18:L22) -> 0 | M23: TOTAL | N23: =SUM(N18:N22) -> 0 | O23: =SUM(O18:O22) -> 0 | P23: =SUM(P18:P22) -> 0 | Q23: =SUM(Q18:Q22) -> 0 | R23: =SUM(R18:R22) -> 0 | S23: =SUM(S18:S22) -> 0 | T23: =SUM(T18:T22) -> 0
A24: Interdiction Unit Total | B24: =SUM(B16,B23,) -> 0 | C24: =SUM(C16,C23) -> 0 | D24: =SUM(D16,D23) -> 0 | E24: =SUM(E16,E23) -> 0 | F24: =SUM(F16,F23) -> 0 | G24: =SUM(G16,G23) -> 0 | H24: =SUM(H16,H23) -> 0 | I24: =SUM(I16,I23) -> 0 | J24: =SUM(J16,J23) -> 0 | ... L24: =SUM(L16,L23) -> 0 | M24: Scott Weaver
B25: UNIFORM NARCOTICS DETECTIVE | M25: Week 1
A26: NAME | B26: Hours Worked | C26: Time Off | D26: K9 Deploy | E26: TNO Cases | F26: Training Hours | G26: Surv. Hours | H26: Patrol/Jail Cases | I26: Traffic Stops | J26: Warrant Arrests | K26: Agency Assist | L26: Supp. reports | M26: Week 2
A27: Scott Weaver | M27: Week 3
A28: Week 1 | M28: Week 4
A29: Week 2 | M29: Week 5
A30: Week 3 | M30: TOTAL | N30: =SUM(N25:N29) -> 0 | O30: =SUM(O25:O29) -> 0 | P30: =SUM(P25:P29) -> 0 | Q30: =SUM(Q25:Q29) -> 0 | R30: =SUM(R25:R29) -> 0 | S30: =SUM(S25:S29) -> 0 | T30: =SUM(T25:T29) -> 0
A31: Week 4 | M31: Brian Chowns
A32: Week 5 | M32: Week 1
A33: Total | B33: =SUM(B28:B32) -> 0 | C33: =SUM(C28:C32) -> 0 | D33: =SUM(D28:D32) -> 0 | E33: =SUM(E28:E32) -> 0 | F33: =SUM(F28:F32) -> 0 | G33: =SUM(G28:G32) -> 0 | H33: =SUM(H28:H32) -> 0 | I33: =SUM(I28:I32) -> 0 | ... L33: =SUM(L28:L32) -> 0 | M33: Week 2
A34: Brian Chowns | M34: Week 3
A35: Week 1 | M35: Week 4
A36: Week 2 | M36: Week 5
A37: Week 3 | M37: TOTAL | N37: =SUM(N32:N36) -> 0 | O37: =SUM(O32:O36) -> 0 | P37: =SUM(P32:P36) -> 0 | Q37: =SUM(Q32:Q36) -> 0 | R37: =SUM(R32:R36) -> 0 | S37: =SUM(S32:S36) -> 0 | T37: =SUM(T32:T36) -> 0
A38: Week 4 | M38: William Crain
A39: Week 5 | M39: Week 1
A40: Total | B40: =SUM(B35:B39) -> 0 | C40: =SUM(C35:C39) -> 0 | D40: =SUM(D35:D39) -> 0 | E40: =SUM(E35:E39) -> 0 | F40: =SUM(F35:F39) -> 0 | G40: =SUM(G35:G39) -> 0 | H40: =SUM(H35:H39) -> 0 | I40: =SUM(I35:I39) -> 0 | ... L40: =SUM(L35:L39) -> 0 | M40: Week 2
A41: William Crain | M41: Week 3
A42: Week 1 | M42: Week 4
A43: Week 2 | M43: Week 5
A44: Week 3 | M44: TOTAL | N44: =SUM(N39:N43) -> 0 | O44: =SUM(O39:O43) -> 0 | P44: =SUM(P39:P43) -> 0 | Q44: =SUM(Q39:Q43) -> 0 | R44: =SUM(R39:R43) -> 0 | S44: =SUM(S39:S43) -> 0 | T44: =SUM(T39:T43) -> 0
A45: Week 4 | M45: Tamara Spikes
A46: Week 5 | M46: Week 1
A47: Total | B47: =SUM(B42:B46) -> 0 | C47: =SUM(C42:C46) -> 0 | D47: =SUM(D42:D46) -> 0 | E47: =SUM(E42:E46) -> 0 | F47: =SUM(F42:F46) -> 0 | G47: =SUM(G42:G46) -> 0 | H47: =SUM(H42:H46) -> 0 | I47: =SUM(I42:I46) -> 0 | ... L47: =SUM(L42:L46) -> 0 | M47: Week 2
...

Sheet Jul
A1: END OF MONTH ACTIVITY TOTALS INTERDICTION July | N1: Drug Seizures
A2: NAME | B2: Hours Worked | C2: Drug Seizures | D2: Criminal Seizures | E2: Currency Seizures | F2: Training Hours | G2: Vehicle Searches | H2: Assist Narc-Ops | I2: Traffic Stops | J2: Warrant Arrests | K2: PC Arrests | L2: Agency Assist | M2: NAME | N2: Methamphetamine (g) | O2: Cocaine (g) | P2: Heroin (g) | Q2: Fentanyl (g) | R2: Marijuana (OZ) | S2: Promethazine/ Codeine (OZ) | T2: RX Pills (#)
A10: Jake Droddy | M10: Jake Droddy
A11: Week 1 | M11: Week 1
A12: Week 2 | M12: Week 2
A13: Week 3 | M13: Week 3
A14: Week 4 | M14: Week 4
A15: Week 5 | M15: Week 5
A16: Total | B16: =SUM(B11:B15) -> 0 | C16: =SUM(C11:C15) -> 0 | D16: =SUM(D11:D15) -> 0 | E16: =SUM(E11:E15) -> 0 | F16: =SUM(F11:F15) -> 0 | G16: =SUM(G11:G15) -> 0 | H16: =SUM(H11:H15) -> 0 | I16: =SUM(I11:I15) -> 0 | ... L16: =SUM(L11:L15) -> 0 | M16: TOTAL | N16: =SUM(N11:N15) -> 0 | O16: =SUM(O11:O15) -> 0 | P16: =SUM(P11:P15) -> 0 | Q16: =SUM(Q11:Q15) -> 0 | R16: =SUM(S11:S15) -> 0 | S16: =SUM(S11:S15) -> 0 | T16: =SUM(T11:T15) -> 0
A17: Brigitte Morse | M17: Brigitte Morse
A18: Week 1 | M18: Week 1
A19: Week 2 | M19: Week 2
A20: Week 3 | M20: Week 3
A21: Week 4 | M21: Week 4
A22: Week 5 | M22: Week 5
A23: Total | B23: =SUM(B18:B22) -> 0 | C23: =SUM(C18:C22) -> 0 | D23: =SUM(D18:D22) -> 0 | E23: =SUM(E18:E22) -> 0 | F23: =SUM(F18:F22) -> 0 | G23: =SUM(G18:G22) -> 0 | H23: =SUM(H18:H22) -> 0 | I23: =SUM(I18:I22) -> 0 | ... L23: =SUM(L18:L22) -> 0 | M23: TOTAL | N23: =SUM(N18:N22) -> 0 | O23: =SUM(O18:O22) -> 0 | P23: =SUM(P18:P22) -> 0 | Q23: =SUM(Q18:Q22) -> 0 | R23: =SUM(R18:R22) -> 0 | S23: =SUM(S18:S22) -> 0 | T23: =SUM(T18:T22) -> 0
A24: Interdiction Unit Total | B24: =SUM(B16,B23,) -> 0 | C24: =SUM(C16,C23) -> 0 | D24: =SUM(D16,D23) -> 0 | E24: =SUM(E16,E23) -> 0 | F24: =SUM(F16,F23) -> 0 | G24: =SUM(G16,G23) -> 0 | H24: =SUM(H16,H23) -> 0 | I24: =SUM(I16,I23) -> 0 | J24: =SUM(J16,J23) -> 0 | ... L24: =SUM(L16,L23) -> 0 | M24: Scott Weaver
B25: UNIFORM NARCOTICS DETECTIVE | M25: Week 1
A26: NAME | B26: Hours Worked | C26: Time Off | D26: K9 Deploy | E26: TNO Cases | F26: Training Hours | G26: Surv. Hours | H26: Patrol/Jail Cases | I26: Traffic Stops | J26: Warrant Arrests | K26: Agency Assist | L26: Supp. reports | M26: Week 2
A27: Scott Weaver | M27: Week 3
A28: Week 1 | M28: Week 4
A29: Week 2 | M29: Week 5
A30: Week 3 | M30: TOTAL | N30: =SUM(N25:N29) -> 0 | O30: =SUM(O25:O29) -> 0 | P30: =SUM(P25:P29) -> 0 | Q30: =SUM(Q25:Q29) -> 0 | R30: =SUM(R25:R29) -> 0 | S30: =SUM(S25:S29) -> 0 | T30: =SUM(T25:T29) -> 0
A31: Week 4 | M31: Brian Chowns
A32: Week 5 | M32: Week 1
A33: Total | B33: =SUM(B28:B32) -> 0 | C33: =SUM(C28:C32) -> 0 | D33: =SUM(D28:D32) -> 0 | E33: =SUM(E28:E32) -> 0 | F33: =SUM(F28:F32) -> 0 | G33: =SUM(G28:G32) -> 0 | H33: =SUM(H28:H32) -> 0 | I33: =SUM(I28:I32) -> 0 | ... L33: =SUM(L28:L32) -> 0 | M33: Week 2
A34: Brian Chowns | M34: Week 3
A35: Week 1 | M35: Week 4
A36: Week 2 | M36: Week 5
A37: Week 3 | M37: TOTAL | N37: =SUM(N32:N36) -> 0 | O37: =SUM(O32:O36) -> 0 | P37: =SUM(P32:P36) -> 0 | Q37: =SUM(Q32:Q36) -> 0 | R37: =SUM(R32:R36) -> 0 | S37: =SUM(S32:S36) -> 0 | T37: =SUM(T32:T36) -> 0
A38: Week 4 | M38: William Crain
A39: Week 5 | M39: Week 1
A40: Total | B40: =SUM(B35:B39) -> 0 | C40: =SUM(C35:C39) -> 0 | D40: =SUM(D35:D39) -> 0 | E40: =SUM(E35:E39) -> 0 | F40: =SUM(F35:F39) -> 0 | G40: =SUM(G35:G39) -> 0 | H40: =SUM(H35:H39) -> 0 | I40: =SUM(I35:I39) -> 0 | ... L40: =SUM(L35:L39) -> 0 | M40: Week 2
A41: William Crain | M41: Week 3
A42: Week 1 | M42: Week 4
A43: Week 2 | M43: Week 5
A44: Week 3 | M44: TOTAL | N44: =SUM(N39:N43) -> 0 | O44: =SUM(O39:O43) -> 0 | P44: =SUM(P39:P43) -> 0 | Q44: =SUM(Q39:Q43) -> 0 | R44: =SUM(R39:R43) -> 0 | S44: =SUM(S39:S43) -> 0 | T44: =SUM(T39:T43) -> 0
A45: Week 4 | M45: Tamara Spikes
A46: Week 5 | M46: Week 1
A47: Total | B47: =SUM(B42:B46) -> 0 | C47: =SUM(C42:C46) -> 0 | D47: =SUM(D42:D46) -> 0 | E47: =SUM(E42:E46) -> 0 | F47: =SUM(F42:F46) -> 0 | G47: =SUM(G42:G46) -> 0 | H47: =SUM(H42:H46) -> 0 | I47: =SUM(I42:I46) -> 0 | ... L47: =SUM(L42:L46) -> 0 | M47: Week 2
...

Sheet Aug
A1: END OF MONTH ACTIVITY TOTALS INTERDICTION August | N1: Drug Seizures
A2: NAME | B2: Hours Worked | C2: Drug Seizures | D2: Criminal Seizures | E2: Currency Seizures | F2: Training Hours | G2: Vehicle Searches | H2: Assist Narc-Ops | I2: Traffic Stops | J2: Warrant Arrests | K2: PC Arrests | L2: Agency Assist | M2: NAME | N2: Methamphetamine (g) | O2: Cocaine (g) | P2: Heroin (g) | Q2: Fentanyl (g) | R2: Marijuana (OZ) | S2: Promethazine/ Codeine (OZ) | T2: RX Pills (#)
A10: Jake Droddy | M10: Jake Droddy
A11: Week 1 | M11: Week 1
A12: Week 2 | M12: Week 2
A13: Week 3 | M13: Week 3
A14: Week 4 | M14: Week 4
A15: Week 5 | M15: Week 5
A16: Total | B16: =SUM(B11:B15) -> 0 | C16: =SUM(C11:C15) -> 0 | D16: =SUM(D11:D15) -> 0 | E16: =SUM(E11:E15) -> 0 | F16: =SUM(F11:F15) -> 0 | G16: =SUM(G11:G15) -> 0 | H16: =SUM(H11:H15) -> 0 | I16: =SUM(I11:I15) -> 0 | ... L16: =SUM(L11:L15) -> 0 | M16: TOTAL | N16: =SUM(N11:N15) -> 0 | O16: =SUM(O11:O15) -> 0 | P16: =SUM(P11:P15) -> 0 | Q16: =SUM(Q11:Q15) -> 0 | R16: =SUM(S11:S15) -> 0 | S16: =SUM(S11:S15) -> 0 | T16: =SUM(T11:T15) -> 0
A17: Brigitte Morse | M17: Brigitte Morse
A18: Week 1 | M18: Week 1
A19: Week 2 | M19: Week 2
A20: Week 3 | M20: Week 3
A21: Week 4 | M21: Week 4
A22: Week 5 | M22: Week 5
A23: Total | B23: =SUM(B18:B22) -> 0 | C23: =SUM(C18:C22) -> 0 | D23: =SUM(D18:D22) -> 0 | E23: =SUM(E18:E22) -> 0 | F23: =SUM(F18:F22) -> 0 | G23: =SUM(G18:G22) -> 0 | H23: =SUM(H18:H22) -> 0 | I23: =SUM(I18:I22) -> 0 | ... L23: =SUM(L18:L22) -> 0 | M23: TOTAL | N23: =SUM(N18:N22) -> 0 | O23: =SUM(O18:O22) -> 0 | P23: =SUM(P18:P22) -> 0 | Q23: =SUM(Q18:Q22) -> 0 | R23: =SUM(R18:R22) -> 0 | S23: =SUM(S18:S22) -> 0 | T23: =SUM(T18:T22) -> 0
A24: Interdiction Unit Total | B24: =SUM(B16,B23,) -> 0 | C24: =SUM(C16,C23) -> 0 | D24: =SUM(D16,D23) -> 0 | E24: =SUM(E16,E23) -> 0 | F24: =SUM(F16,F23) -> 0 | G24: =SUM(G16,G23) -> 0 | H24: =SUM(H16,H23) -> 0 | I24: =SUM(I16,I23) -> 0 | J24: =SUM(J16,J23) -> 0 | ... L24: =SUM(L16,L23) -> 0 | M24: Scott Weaver
B25: UNIFORM NARCOTICS DETECTIVE | M25: Week 1
A26: NAME | B26: Hours Worked | C26: Time Off | D26: K9 Deploy | E26: TNO Cases | F26: Training Hours | G26: Surv. Hours | H26: Patrol/Jail Cases | I26: Traffic Stops | J26: Warrant Arrests | K26: Agency Assist | L26: Supp. reports | M26: Week 2
A27: Scott Weaver | M27: Week 3
A28: Week 1 | M28: Week 4
A29: Week 2 | M29: Week 5
A30: Week 3 | M30: TOTAL | N30: =SUM(N25:N29) -> 0 | O30: =SUM(O25:O29) -> 0 | P30: =SUM(P25:P29) -> 0 | Q30: =SUM(Q25:Q29) -> 0 | R30: =SUM(R25:R29) -> 0 | S30: =SUM(S25:S29) -> 0 | T30: =SUM(T25:T29) -> 0
A31: Week 4 | M31: Brian Chowns
A32: Week 5 | M32: Week 1
A33: Total | B33: =SUM(B28:B32) -> 0 | C33: =SUM(C28:C32) -> 0 | D33: =SUM(D28:D32) -> 0 | E33: =SUM(E28:E32) -> 0 | F33: =SUM(F28:F32) -> 0 | G33: =SUM(G28:G32) -> 0 | H33: =SUM(H28:H32) -> 0 | I33: =SUM(I28:I32) -> 0 | ... L33: =SUM(L28:L32) -> 0 | M33: Week 2
A34: Brian Chowns | M34: Week 3
A35: Week 1 | M35: Week 4
A36: Week 2 | M36: Week 5
A37: Week 3 | M37: TOTAL | N37: =SUM(N32:N36) -> 0 | O37: =SUM(O32:O36) -> 0 | P37: =SUM(P32:P36) -> 0 | Q37: =SUM(Q32:Q36) -> 0 | R37: =SUM(R32:R36) -> 0 | S37: =SUM(S32:S36) -> 0 | T37: =SUM(T32:T36) -> 0
A38: Week 4 | M38: William Crain
A39: Week 5 | M39: Week 1
A40: Total | B40: =SUM(B35:B39) -> 0 | C40: =SUM(C35:C39) -> 0 | D40: =SUM(D35:D39) -> 0 | E40: =SUM(E35:E39) -> 0 | F40: =SUM(F35:F39) -> 0 | G40: =SUM(G35:G39) -> 0 | H40: =SUM(H35:H39) -> 0 | I40: =SUM(I35:I39) -> 0 | ... L40: =SUM(L35:L39) -> 0 | M40: Week 2
A41: William Crain | M41: Week 3
A42: Week 1 | M42: Week 4
A43: Week 2 | M43: Week 5
A44: Week 3 | M44: TOTAL | N44: =SUM(N39:N43) -> 0 | O44: =SUM(O39:O43) -> 0 | P44: =SUM(P39:P43) -> 0 | Q44: =SUM(Q39:Q43) -> 0 | R44: =SUM(R39:R43) -> 0 | S44: =SUM(S39:S43) -> 0 | T44: =SUM(T39:T43) -> 0
A45: Week 4 | M45: Tamara Spikes
A46: Week 5 | M46: Week 1
A47: Total | B47: =SUM(B42:B46) -> 0 | C47: =SUM(C42:C46) -> 0 | D47: =SUM(D42:D46) -> 0 | E47: =SUM(E42:E46) -> 0 | F47: =SUM(F42:F46) -> 0 | G47: =SUM(G42:G46) -> 0 | H47: =SUM(H42:H46) -> 0 | I47: =SUM(I42:I46) -> 0 | ... L47: =SUM(L42:L46) -> 0 | M47: Week 2
...

Sheet Sep
A1: END OF MONTH ACTIVITY TOTALS INTERDICTION September | N1: Drug Seizures
A2: NAME | B2: Hours Worked | C2: Drug Seizures | D2: Criminal Seizures | E2: Currency Seizures | F2: Training Hours | G2: Vehicle Searches | H2: Assist Narc-Ops | I2: Traffic Stops | J2: Warrant Arrests | K2: PC Arrests | L2: Agency Assist | M2: NAME | N2: Methamphetamine (g) | O2: Cocaine (g) | P2: Heroin (g) | Q2: Fentanyl (g) | R2: Marijuana (OZ) | S2: Promethazine/ Codeine (OZ) | T2: RX Pills (#)
A10: Jake Droddy | M10: Jake Droddy
A11: Week 1 | M11: Week 1
A12: Week 2 | M12: Week 2
A13: Week 3 | M13: Week 3
A14: Week 4 | M14: Week 4
A15: Week 5 | M15: Week 5
A16: Total | B16: =SUM(B11:B15) -> 0 | C16: =SUM(C11:C15) -> 0 | D16: =SUM(D11:D15) -> 0 | E16: =SUM(E11:E15) -> 0 | F16: =SUM(F11:F15) -> 0 | G16: =SUM(G11:G15) -> 0 | H16: =SUM(H11:H15) -> 0 | I16: =SUM(I11:I15) -> 0 | ... L16: =SUM(L11:L15) -> 0 | M16: TOTAL | N16: =SUM(N11:N15) -> 0 | O16: =SUM(O11:O15) -> 0 | P16: =SUM(P11:P15) -> 0 | Q16: =SUM(Q11:Q15) -> 0 | R16: =SUM(S11:S15) -> 0 | S16: =SUM(S11:S15) -> 0 | T16: =SUM(T11:T15) -> 0
A17: Brigitte Morse | M17: Brigitte Morse
A18: Week 1 | M18: Week 1
A19: Week 2 | M19: Week 2
A20: Week 3 | M20: Week 3
A21: Week 4 | M21: Week 4
A22: Week 5 | M22: Week 5
A23: Total | B23: =SUM(B18:B22) -> 0 | C23: =SUM(C18:C22) -> 0 | D23: =SUM(D18:D22) -> 0 | E23: =SUM(E18:E22) -> 0 | F23: =SUM(F18:F22) -> 0 | G23: =SUM(G18:G22) -> 0 | H23: =SUM(H18:H22) -> 0 | I23: =SUM(I18:I22) -> 0 | ... L23: =SUM(L18:L22) -> 0 | M23: TOTAL | N23: =SUM(N18:N22) -> 0 | O23: =SUM(O18:O22) -> 0 | P23: =SUM(P18:P22) -> 0 | Q23: =SUM(Q18:Q22) -> 0 | R23: =SUM(R18:R22) -> 0 | S23: =SUM(S18:S22) -> 0 | T23: =SUM(T18:T22) -> 0
A24: Interdiction Unit Total | B24: =SUM(B16,B23,) -> 0 | C24: =SUM(C16,C23) -> 0 | D24: =SUM(D16,D23) -> 0 | E24: =SUM(E16,E23) -> 0 | F24: =SUM(F16,F23) -> 0 | G24: =SUM(G16,G23) -> 0 | H24: =SUM(H16,H23) -> 0 | I24: =SUM(I16,I23) -> 0 | J24: =SUM(J16,J23) -> 0 | ... L24: =SUM(L16,L23) -> 0 | M24: Scott Weaver
B25: UNIFORM NARCOTICS DETECTIVE | M25: Week 1
A26: NAME | B26: Hours Worked | C26: Time Off | D26: K9 Deploy | E26: TNO Cases | F26: Training Hours | G26: Surv. Hours | H26: Patrol/Jail Cases | I26: Traffic Stops | J26: Warrant Arrests | K26: Agency Assist | L26: Supp. reports | M26: Week 2
A27: Scott Weaver | M27: Week 3
A28: Week 1 | M28: Week 4
A29: Week 2 | M29: Week 5
A30: Week 3 | M30: TOTAL | N30: =SUM(N25:N29) -> 0 | O30: =SUM(O25:O29) -> 0 | P30: =SUM(P25:P29) -> 0 | Q30: =SUM(Q25:Q29) -> 0 | R30: =SUM(R25:R29) -> 0 | S30: =SUM(S25:S29) -> 0 | T30: =SUM(T25:T29) -> 0
A31: Week 4 | M31: Brian Chowns
A32: Week 5 | M32: Week 1
A33: Total | B33: =SUM(B28:B32) -> 0 | C33: =SUM(C28:C32) -> 0 | D33: =SUM(D28:D32) -> 0 | E33: =SUM(E28:E32) -> 0 | F33: =SUM(F28:F32) -> 0 | G33: =SUM(G28:G32) -> 0 | H33: =SUM(H28:H32) -> 0 | I33: =SUM(I28:I32) -> 0 | ... L33: =SUM(L28:L32) -> 0 | M33: Week 2
A34: Brian Chowns | M34: Week 3
A35: Week 1 | M35: Week 4
A36: Week 2 | M36: Week 5
A37: Week 3 | M37: TOTAL | N37: =SUM(N32:N36) -> 0 | O37: =SUM(O32:O36) -> 0 | P37: =SUM(P32:P36) -> 0 | Q37: =SUM(Q32:Q36) -> 0 | R37: =SUM(R32:R36) -> 0 | S37: =SUM(S32:S36) -> 0 | T37: =SUM(T32:T36) -> 0
A38: Week 4 | M38: William Crain
A39: Week 5 | M39: Week 1
A40: Total | B40: =SUM(B35:B39) -> 0 | C40: =SUM(C35:C39) -> 0 | D40: =SUM(D35:D39) -> 0 | E40: =SUM(E35:E39) -> 0 | F40: =SUM(F35:F39) -> 0 | G40: =SUM(G35:G39) -> 0 | H40: =SUM(H35:H39) -> 0 | I40: =SUM(I35:I39) -> 0 | ... L40: =SUM(L35:L39) -> 0 | M40: Week 2
A41: William Crain | M41: Week 3
A42: Week 1 | M42: Week 4
A43: Week 2 | M43: Week 5
A44: Week 3 | M44: TOTAL | N44: =SUM(N39:N43) -> 0 | O44: =SUM(O39:O43) -> 0 | P44: =SUM(P39:P43) -> 0 | Q44: =SUM(Q39:Q43) -> 0 | R44: =SUM(R39:R43) -> 0 | S44: =SUM(S39:S43) -> 0 | T44: =SUM(T39:T43) -> 0
A45: Week 4 | M45: Tamara Spikes
A46: Week 5 | M46: Week 1
A47: Total | B47: =SUM(B42:B46) -> 0 | C47: =SUM(C42:C46) -> 0 | D47: =SUM(D42:D46) -> 0 | E47: =SUM(E42:E46) -> 0 | F47: =SUM(F42:F46) -> 0 | G47: =SUM(G42:G46) -> 0 | H47: =SUM(H42:H46) -> 0 | I47: =SUM(I42:I46) -> 0 | ... L47: =SUM(L42:L46) -> 0 | M47: Week 2
...

Sheet Oct
A1: END OF MONTH ACTIVITY TOTALS INTERDICTION October | N1: Drug Seizures
A2: NAME | B2: Hours Worked | C2: Drug Seizures | D2: Criminal Seizures | E2: Currency Seizures | F2: Training Hours | G2: Vehicle Searches | H2: Assist Narc-Ops | I2: Traffic Stops | J2: Warrant Arrests | K2: PC Arrests | L2: Agency Assist | M2: NAME | N2: Methamphetamine (g) | O2: Cocaine (g) | P2: Heroin (g) | Q2: Fentanyl (g) | R2: Marijuana (OZ) | S2: Promethazine/ Codeine (OZ) | T2: RX Pills (#)
A10: Jake Droddy | M10: Jake Droddy
A11: Week 1 | M11: Week 1
A12: Week 2 | M12: Week 2
A13: Week 3 | M13: Week 3
A14: Week 4 | M14: Week 4
A15: Week 5 | M15: Week 5
A16: Total | B16: =SUM(B11:B15) -> 0 | C16: =SUM(C11:C15) -> 0 | D16: =SUM(D11:D15) -> 0 | E16: =SUM(E11:E15) -> 0 | F16: =SUM(F11:F15) -> 0 | G16: =SUM(G11:G15) -> 0 | H16: =SUM(H11:H15) -> 0 | I16: =SUM(I11:I15) -> 0 | ... L16: =SUM(L11:L15) -> 0 | M16: TOTAL | N16: =SUM(N11:N15) -> 0 | O16: =SUM(O11:O15) -> 0 | P16: =SUM(P11:P15) -> 0 | Q16: =SUM(Q11:Q15) -> 0 | R16: =SUM(S11:S15) -> 0 | S16: =SUM(S11:S15) -> 0 | T16: =SUM(T11:T15) -> 0
A17: Brigitte Morse | M17: Brigitte Morse
A18: Week 1 | M18: Week 1
A19: Week 2 | M19: Week 2
A20: Week 3 | M20: Week 3
A21: Week 4 | M21: Week 4
A22: Week 5 | M22: Week 5
A23: Total | B23: =SUM(B18:B22) -> 0 | C23: =SUM(C18:C22) -> 0 | D23: =SUM(D18:D22) -> 0 | E23: =SUM(E18:E22) -> 0 | F23: =SUM(F18:F22) -> 0 | G23: =SUM(G18:G22) -> 0 | H23: =SUM(H18:H22) -> 0 | I23: =SUM(I18:I22) -> 0 | ... L23: =SUM(L18:L22) -> 0 | M23: TOTAL | N23: =SUM(N18:N22) -> 0 | O23: =SUM(O18:O22) -> 0 | P23: =SUM(P18:P22) -> 0 | Q23: =SUM(Q18:Q22) -> 0 | R23: =SUM(R18:R22) -> 0 | S23: =SUM(S18:S22) -> 0 | T23: =SUM(T18:T22) -> 0
A24: Interdiction Unit Total | B24: =SUM(B16,B23,) -> 0 | C24: =SUM(C16,C23) -> 0 | D24: =SUM(D16,D23) -> 0 | E24: =SUM(E16,E23) -> 0 | F24: =SUM(F16,F23) -> 0 | G24: =SUM(G16,G23) -> 0 | H24: =SUM(H16,H23) -> 0 | I24: =SUM(I16,I23) -> 0 | J24: =SUM(J16,J23) -> 0 | ... L24: =SUM(L16,L23) -> 0 | M24: Scott Weaver
B25: UNIFORM NARCOTICS DETECTIVE | M25: Week 1
A26: NAME | B26: Hours Worked | C26: Time Off | D26: K9 Deploy | E26: TNO Cases | F26: Training Hours | G26: Surv. Hours | H26: Patrol/Jail Cases | I26: Traffic Stops | J26: Warrant Arrests | K26: Agency Assist | L26: Supp. reports | M26: Week 2
A27: Scott Weaver | M27: Week 3
A28: Week 1 | M28: Week 4
A29: Week 2 | M29: Week 5
A30: Week 3 | M30: TOTAL | N30: =SUM(N25:N29) -> 0 | O30: =SUM(O25:O29) -> 0 | P30: =SUM(P25:P29) -> 0 | Q30: =SUM(Q25:Q29) -> 0 | R30: =SUM(R25:R29) -> 0 | S30: =SUM(S25:S29) -> 0 | T30: =SUM(T25:T29) -> 0
A31: Week 4 | M31: Brian Chowns
A32: Week 5 | M32: Week 1
A33: Total | B33: =SUM(B28:B32) -> 0 | C33: =SUM(C28:C32) -> 0 | D33: =SUM(D28:D32) -> 0 | E33: =SUM(E28:E32) -> 0 | F33: =SUM(F28:F32) -> 0 | G33: =SUM(G28:G32) -> 0 | H33: =SUM(H28:H32) -> 0 | I33: =SUM(I28:I32) -> 0 | ... L33: =SUM(L28:L32) -> 0 | M33: Week 2
A34: Brian Chowns | M34: Week 3
A35: Week 1 | M35: Week 4
A36: Week 2 | M36: Week 5
A37: Week 3 | M37: TOTAL | N37: =SUM(N32:N36) -> 0 | O37: =SUM(O32:O36) -> 0 | P37: =SUM(P32:P36) -> 0 | Q37: =SUM(Q32:Q36) -> 0 | R37: =SUM(R32:R36) -> 0 | S37: =SUM(S32:S36) -> 0 | T37: =SUM(T32:T36) -> 0
A38: Week 4 | M38: William Crain
A39: Week 5 | M39: Week 1
A40: Total | B40: =SUM(B35:B39) -> 0 | C40: =SUM(C35:C39) -> 0 | D40: =SUM(D35:D39) -> 0 | E40: =SUM(E35:E39) -> 0 | F40: =SUM(F35:F39) -> 0 | G40: =SUM(G35:G39) -> 0 | H40: =SUM(H35:H39) -> 0 | I40: =SUM(I35:I39) -> 0 | ... L40: =SUM(L35:L39) -> 0 | M40: Week 2
A41: William Crain | M41: Week 3
A42: Week 1 | M42: Week 4
A43: Week 2 | M43: Week 5
A44: Week 3 | M44: TOTAL | N44: =SUM(N39:N43) -> 0 | O44: =SUM(O39:O43) -> 0 | P44: =SUM(P39:P43) -> 0 | Q44: =SUM(Q39:Q43) -> 0 | R44: =SUM(R39:R43) -> 0 | S44: =SUM(S39:S43) -> 0 | T44: =SUM(T39:T43) -> 0
A45: Week 4 | M45: Tamara Spikes
A46: Week 5 | M46: Week 1
A47: Total | B47: =SUM(B42:B46) -> 0 | C47: =SUM(C42:C46) -> 0 | D47: =SUM(D42:D46) -> 0 | E47: =SUM(E42:E46) -> 0 | F47: =SUM(F42:F46) -> 0 | G47: =SUM(G42:G46) -> 0 | H47: =SUM(H42:H46) -> 0 | I47: =SUM(I42:I46) -> 0 | ... L47: =SUM(L42:L46) -> 0 | M47: Week 2
...

Sheet Nov
A1: END OF MONTH ACTIVITY TOTALS INTERDICTION November | N1: Drug Seizures
A2: NAME | B2: Hours Worked | C2: Drug Seizures | D2: Criminal Seizures | E2: Currency Seizures | F2: Training Hours | G2: Vehicle Searches | H2: Assist Narc-Ops | I2: Traffic Stops | J2: Warrant Arrests | K2: PC Arrests | L2: Agency Assist | M2: NAME | N2: Methamphetamine (g) | O2: Cocaine (g) | P2: Heroin (g) | Q2: Fentanyl (g) | R2: Marijuana (OZ) | S2: Promethazine/ Codeine (OZ) | T2: RX Pills (#)
A10: Jake Droddy | M10: Jake Droddy
A11: Week 1 | M11: Week 1
A12: Week 2 | M12: Week 2
A13: Week 3 | M13: Week 3
A14: Week 4 | M14: Week 4
A15: Week 5 | M15: Week 5
A16: Total | B16: =SUM(B11:B15) -> 0 | C16: =SUM(C11:C15) -> 0 | D16: =SUM(D11:D15) -> 0 | E16: =SUM(E11:E15) -> 0 | F16: =SUM(F11:F15) -> 0 | G16: =SUM(G11:G15) -> 0 | H16: =SUM(H11:H15) -> 0 | I16: =SUM(I11:I15) -> 0 | ... L16: =SUM(L11:L15) -> 0 | M16: TOTAL | N16: =SUM(N11:N15) -> 0 | O16: =SUM(O11:O15) -> 0 | P16: =SUM(P11:P15) -> 0 | Q16: =SUM(Q11:Q15) -> 0 | R16: =SUM(S11:S15) -> 0 | S16: =SUM(S11:S15) -> 0 | T16: =SUM(T11:T15) -> 0
A17: Brigitte Morse | M17: Brigitte Morse
A18: Week 1 | M18: Week 1
A19: Week 2 | M19: Week 2
A20: Week 3 | M20: Week 3
A21: Week 4 | M21: Week 4
A22: Week 5 | M22: Week 5
A23: Total | B23: =SUM(B18:B22) -> 0 | C23: =SUM(C18:C22) -> 0 | D23: =SUM(D18:D22) -> 0 | E23: =SUM(E18:E22) -> 0 | F23: =SUM(F18:F22) -> 0 | G23: =SUM(G18:G22) -> 0 | H23: =SUM(H18:H22) -> 0 | I23: =SUM(I18:I22) -> 0 | ... L23: =SUM(L18:L22) -> 0 | M23: TOTAL | N23: =SUM(N18:N22) -> 0 | O23: =SUM(O18:O22) -> 0 | P23: =SUM(P18:P22) -> 0 | Q23: =SUM(Q18:Q22) -> 0 | R23: =SUM(R18:R22) -> 0 | S23: =SUM(S18:S22) -> 0 | T23: =SUM(T18:T22) -> 0
A24: Interdiction Unit Total | B24: =SUM(B16,B23,) -> 0 | C24: =SUM(C16,C23) -> 0 | D24: =SUM(D16,D23) -> 0 | E24: =SUM(E16,E23) -> 0 | F24: =SUM(F16,F23) -> 0 | G24: =SUM(G16,G23) -> 0 | H24: =SUM(H16,H23) -> 0 | I24: =SUM(I16,I23) -> 0 | J24: =SUM(J16,J23) -> 0 | ... L24: =SUM(L16,L23) -> 0 | M24: Scott Weaver
B25: UNIFORM NARCOTICS DETECTIVE | M25: Week 1
A26: NAME | B26: Hours Worked | C26: Time Off | D26: K9 Deploy | E26: TNO Cases | F26: Training Hours | G26: Surv. Hours | H26: Patrol/Jail Cases | I26: Traffic Stops | J26: Warrant Arrests | K26: Agency Assist | L26: Supp. reports | M26: Week 2
A27: Scott Weaver | M27: Week 3
A28: Week 1 | M28: Week 4
A29: Week 2 | M29: Week 5
A30: Week 3 | M30: TOTAL | N30: =SUM(N25:N29) -> 0 | O30: =SUM(O25:O29) -> 0 | P30: =SUM(P25:P29) -> 0 | Q30: =SUM(Q25:Q29) -> 0 | R30: =SUM(R25:R29) -> 0 | S30: =SUM(S25:S29) -> 0 | T30: =SUM(T25:T29) -> 0
A31: Week 4 | M31: Brian Chowns
A32: Week 5 | M32: Week 1
A33: Total | B33: =SUM(B28:B32) -> 0 | C33: =SUM(C28:C32) -> 0 | D33: =SUM(D28:D32) -> 0 | E33: =SUM(E28:E32) -> 0 | F33: =SUM(F28:F32) -> 0 | G33: =SUM(G28:G32) -> 0 | H33: =SUM(H28:H32) -> 0 | I33: =SUM(I28:I32) -> 0 | ... L33: =SUM(L28:L32) -> 0 | M33: Week 2
A34: Brian Chowns | M34: Week 3
A35: Week 1 | M35: Week 4
A36: Week 2 | M36: Week 5
A37: Week 3 | M37: TOTAL | N37: =SUM(N32:N36) -> 0 | O37: =SUM(O32:O36) -> 0 | P37: =SUM(P32:P36) -> 0 | Q37: =SUM(Q32:Q36) -> 0 | R37: =SUM(R32:R36) -> 0 | S37: =SUM(S32:S36) -> 0 | T37: =SUM(T32:T36) -> 0
A38: Week 4 | M38: William Crain
A39: Week 5 | M39: Week 1
A40: Total | B40: =SUM(B35:B39) -> 0 | C40: =SUM(C35:C39) -> 0 | D40: =SUM(D35:D39) -> 0 | E40: =SUM(E35:E39) -> 0 | F40: =SUM(F35:F39) -> 0 | G40: =SUM(G35:G39) -> 0 | H40: =SUM(H35:H39) -> 0 | I40: =SUM(I35:I39) -> 0 | ... L40: =SUM(L35:L39) -> 0 | M40: Week 2
A41: William Crain | M41: Week 3
A42: Week 1 | M42: Week 4
A43: Week 2 | M43: Week 5
A44: Week 3 | M44: TOTAL | N44: =SUM(N39:N43) -> 0 | O44: =SUM(O39:O43) -> 0 | P44: =SUM(P39:P43) -> 0 | Q44: =SUM(Q39:Q43) -> 0 | R44: =SUM(R39:R43) -> 0 | S44: =SUM(S39:S43) -> 0 | T44: =SUM(T39:T43) -> 0
A45: Week 4 | M45: Tamara Spikes
A46: Week 5 | M46: Week 1
A47: Total | B47: =SUM(B42:B46) -> 0 | C47: =SUM(C42:C46) -> 0 | D47: =SUM(D42:D46) -> 0 | E47: =SUM(E42:E46) -> 0 | F47: =SUM(F42:F46) -> 0 | G47: =SUM(G42:G46) -> 0 | H47: =SUM(H42:H46) -> 0 | I47: =SUM(I42:I46) -> 0 | ... L47: =SUM(L42:L46) -> 0 | M47: Week 2
...

Sheet Dec
A1: END OF MONTH ACTIVITY TOTALS INTERDICTION December | N1: Drug Seizures
A2: NAME | B2: Hours Worked | C2: Drug Seizures | D2: Criminal Seizures | E2: Currency Seizures | F2: Training Hours | G2: Vehicle Searches | H2: Assist Narc-Ops | I2: Traffic Stops | J2: Warrant Arrests | K2: PC Arrests | L2: Agency Assist | M2: NAME | N2: Methamphetamine (g) | O2: Cocaine (g) | P2: Heroin (g) | Q2: Fentanyl (g) | R2: Marijuana (OZ) | S2: Promethazine/ Codeine (OZ) | T2: RX Pills (#)
A10: Jake Droddy | M10: Jake Droddy
A11: Week 1 | M11: Week 1
A12: Week 2 | M12: Week 2
A13: Week 3 | M13: Week 3
A14: Week 4 | M14: Week 4
A15: Week 5 | M15: Week 5
A16: Total | B16: =SUM(B11:B15) -> 0 | C16: =SUM(C11:C15) -> 0 | D16: =SUM(D11:D15) -> 0 | E16: =SUM(E11:E15) -> 0 | F16: =SUM(F11:F15) -> 0 | G16: =SUM(G11:G15) -> 0 | H16: =SUM(H11:H15) -> 0 | I16: =SUM(I11:I15) -> 0 | ... L16: =SUM(L11:L15) -> 0 | M16: TOTAL | N16: =SUM(N11:N15) -> 0 | O16: =SUM(O11:O15) -> 0 | P16: =SUM(P11:P15) -> 0 | Q16: =SUM(Q11:Q15) -> 0 | R16: =SUM(S11:S15) -> 0 | S16: =SUM(S11:S15) -> 0 | T16: =SUM(T11:T15) -> 0
A17: Brigitte Morse | M17: Brigitte Morse
A18: Week 1 | M18: Week 1
A19: Week 2 | M19: Week 2
A20: Week 3 | M20: Week 3
A21: Week 4 | M21: Week 4
A22: Week 5 | M22: Week 5
A23: Total | B23: =SUM(B18:B22) -> 0 | C23: =SUM(C18:C22) -> 0 | D23: =SUM(D18:D22) -> 0 | E23: =SUM(E18:E22) -> 0 | F23: =SUM(F18:F22) -> 0 | G23: =SUM(G18:G22) -> 0 | H23: =SUM(H18:H22) -> 0 | I23: =SUM(I18:I22) -> 0 | ... L23: =SUM(L18:L22) -> 0 | M23: TOTAL | N23: =SUM(N18:N22) -> 0 | O23: =SUM(O18:O22) -> 0 | P23: =SUM(P18:P22) -> 0 | Q23: =SUM(Q18:Q22) -> 0 | R23: =SUM(R18:R22) -> 0 | S23: =SUM(S18:S22) -> 0 | T23: =SUM(T18:T22) -> 0
A24: Interdiction Unit Total | B24: =SUM(B16,B23,) -> 0 | C24: =SUM(C16,C23) -> 0 | D24: =SUM(D16,D23) -> 0 | E24: =SUM(E16,E23) -> 0 | F24: =SUM(F16,F23) -> 0 | G24: =SUM(G16,G23) -> 0 | H24: =SUM(H16,H23) -> 0 | I24: =SUM(I16,I23) -> 0 | J24: =SUM(J16,J23) -> 0 | ... L24: =SUM(L16,L23) -> 0 | M24: Scott Weaver
B25: UNIFORM NARCOTICS DETECTIVE | M25: Week 1
A26: NAME | B26: Hours Worked | C26: Time Off | D26: K9 Deploy | E26: TNO Cases | F26: Training Hours | G26: Surv. Hours | H26: Patrol/Jail Cases | I26: Traffic Stops | J26: Warrant Arrests | K26: Agency Assist | L26: Supp. reports | M26: Week 2
A27: Scott Weaver | M27: Week 3
A28: Week 1 | M28: Week 4
A29: Week 2 | M29: Week 5
A30: Week 3 | M30: TOTAL | N30: =SUM(N25:N29) -> 0 | O30: =SUM(O25:O29) -> 0 | P30: =SUM(P25:P29) -> 0 | Q30: =SUM(Q25:Q29) -> 0 | R30: =SUM(R25:R29) -> 0 | S30: =SUM(S25:S29) -> 0 | T30: =SUM(T25:T29) -> 0
A31: Week 4 | M31: Brian Chowns
A32: Week 5 | M32: Week 1
A33: Total | B33: =SUM(B28:B32) -> 0 | C33: =SUM(C28:C32) -> 0 | D33: =SUM(D28:D32) -> 0 | E33: =SUM(E28:E32) -> 0 | F33: =SUM(F28:F32) -> 0 | G33: =SUM(G28:G32) -> 0 | H33: =SUM(H28:H32) -> 0 | I33: =SUM(I28:I32) -> 0 | ... L33: =SUM(L28:L32) -> 0 | M33: Week 2
A34: Brian Chowns | M34: Week 3
A35: Week 1 | M35: Week 4
A36: Week 2 | M36: Week 5
A37: Week 3 | M37: TOTAL | N37: =SUM(N32:N36) -> 0 | O37: =SUM(O32:O36) -> 0 | P37: =SUM(P32:P36) -> 0 | Q37: =SUM(Q32:Q36) -> 0 | R37: =SUM(R32:R36) -> 0 | S37: =SUM(S32:S36) -> 0 | T37: =SUM(T32:T36) -> 0
A38: Week 4 | M38: William Crain
A39: Week 5 | M39: Week 1
A40: Total | B40: =SUM(B35:B39) -> 0 | C40: =SUM(C35:C39) -> 0 | D40: =SUM(D35:D39) -> 0 | E40: =SUM(E35:E39) -> 0 | F40: =SUM(F35:F39) -> 0 | G40: =SUM(G35:G39) -> 0 | H40: =SUM(H35:H39) -> 0 | I40: =SUM(I35:I39) -> 0 | ... L40: =SUM(L35:L39) -> 0 | M40: Week 2
A41: William Crain | M41: Week 3
A42: Week 1 | M42: Week 4
A43: Week 2 | M43: Week 5
A44: Week 3 | M44: TOTAL | N44: =SUM(N39:N43) -> 0 | O44: =SUM(O39:O43) -> 0 | P44: =SUM(P39:P43) -> 0 | Q44: =SUM(Q39:Q43) -> 0 | R44: =SUM(R39:R43) -> 0 | S44: =SUM(S39:S43) -> 0 | T44: =SUM(T39:T43) -> 0
A45: Week 4 | M45: Tamara Spikes
A46: Week 5 | M46: Week 1
A47: Total | B47: =SUM(B42:B46) -> 0 | C47: =SUM(C42:C46) -> 0 | D47: =SUM(D42:D46) -> 0 | E47: =SUM(E42:E46) -> 0 | F47: =SUM(F42:F46) -> 0 | G47: =SUM(G42:G46) -> 0 | H47: =SUM(H42:H46) -> 0 | I47: =SUM(I42:I46) -> 0 | ... L47: =SUM(L42:L46) -> 0 | M47: Week 2
...

Sheet Year Total
A1: End of Year Interdiction
A2: Month | B2: Jan. | C2: Feb. | D2: March | E2: April | F2: May | G2: June | H2: July | I2: Aug. | J2: Sept. | K2: Oct. | L2: Nov. | M2: Dec. | N2: TOTAL
A3: Drug Seizures | B3: =Jan!$C$24 -> 0 | C3: =Feb!$C$24 -> 0 | D3: =Mar!$C$24 -> 0 | E3: =Apr!$C$24 -> 0 | F3: =May!$C$24 -> 0 | G3: =Jun!$C$24 -> 0 | H3: =Jul!$C$24 -> 0 | I3: =Aug!$C$24 -> 0 | J3: =Sep!$C$24 -> 0 | K3: =Oct!$C$24 -> 0 | L3: =Nov!$C$24 -> 0 | M3: =Dec!$C$24 -> 0 | N3: =SUM(B3:M3) -> 0
A4: Criminal Seizures | B4: =Jan!$D$24 -> 0 | C4: =Feb!$D$24 -> 0 | D4: =Mar!$D$24 -> 0 | E4: =Apr!$D$24 -> 0 | F4: =May!$C$24 -> 0 | G4: =Jun!$C$24 -> 0 | H4: =Jul!$C$24 -> 0 | I4: =Aug!$C$24 -> 0 | J4: =Sep!$C$24 -> 0 | K4: =Oct!$C$24 -> 0 | L4: =Nov!$C$24 -> 0 | M4: =Dec!$C$24 -> 0 | N4: =SUM(B4:M4) -> 0
A5: Currency Seizures | B5: =Jan!$E$24 -> 0 | C5: =Feb!$E$24 -> 0 | D5: =Mar!$E$24 -> 0 | E5: =Apr!$E$24 -> 0 | F5: =May!$C$24 -> 0 | G5: =Jun!$C$24 -> 0 | H5: =Jul!$C$24 -> 0 | I5: =Aug!$C$24 -> 0 | J5: =Sep!$C$24 -> 0 | K5: =Oct!$C$24 -> 0 | L5: =Nov!$C$24 -> 0 | M5: =Dec!$C$24 -> 0 | N5: =SUM(B5:M5) -> 0
A6: Training Hours | B6: =Jan!$F$24 -> 0 | C6: =Feb!$F$24 -> 0 | D6: =Mar!$F$24 -> 0 | E6: =Apr!$F$24 -> 0 | F6: =May!$F$24 -> 0 | G6: =Jun!$F$24 -> 0 | H6: =Jul!$F$24 -> 0 | I6: =Aug!$F$24 -> 0 | J6: =Sep!$F$24 -> 0 | K6: =Oct!$F$24 -> 0 | L6: =Nov!$F$24 -> 0 | M6: =Dec!$F$24 -> 0 | N6: =SUM(B6:M6) -> 0
A7: Vehicle Searches | B7: =Jan!$G$24 -> 0 | C7: =Feb!$G$24 -> 0 | D7: =Mar!$G$24 -> 0 | E7: =Apr!$G$24 -> 0 | F7: =May!$G$24 -> 0 | G7: =Jun!$G$24 -> 0 | H7: =Jul!$G$24 -> 0 | I7: =Aug!$G$24 -> 0 | J7: =Sep!$G$24 -> 0 | K7: =Oct!$G$24 -> 0 | L7: =Nov!$G$24 -> 0 | M7: =Dec!$G$24 -> 0 | N7: =SUM(B7:M7) -> 0
A8: Assist Narc-Ops | B8: =Jan!$H$24 -> 0 | C8: =Feb!$H$24 -> 0 | D8: =Mar!$H$24 -> 0 | E8: =Apr!$H$24 -> 0 | F8: =May!$H$24 -> 0 | G8: =Jun!$H$24 -> 0 | H8: =Jul!$H$24 -> 0 | I8: =Aug!$H$24 -> 0 | J8: =Sep!$H$24 -> 0 | K8: =Oct!$H$24 -> 0 | L8: =Nov!$H$24 -> 0 | M8: =Dec!$H$24 -> 0 | N8: =SUM(B8:M8) -> 0
A9: Traffic Stops | B9: =Jan!$I$24 -> 0 | C9: =Feb!$I$24 -> 0 | D9: =Mar!$I$24 -> 0 | E9: =Apr!$I$24 -> 0 | F9: =May!$I$24 -> 0 | G9: =Jun!$I$24 -> 0 | H9: =Jul!$I$24 -> 0 | I9: =Aug!$I$24 -> 0 | J9: =Sep!$I$24 -> 0 | K9: =Oct!$I$24 -> 0 | L9: =Nov!$I$24 -> 0 | M9: =Dec!$I$24 -> 0 | N9: =SUM(B9:M9) -> 0
A10: Warrant Arrests | B10: =Jan!$J$24 -> 0 | C10: =Feb!$J$24 -> 0 | D10: =Mar!$J$24 -> 0 | E10: =Apr!$J$24 -> 0 | F10: =May!$J$24 -> 0 | G10: =Jun!$J$24 -> 0 | H10: =Jul!$J$24 -> 0 | I10: =Aug!$J$24 -> 0 | J10: =Sep!$J$24 -> 0 | K10: =Oct!$J$24 -> 0 | L10: =Nov!$J$24 -> 0 | M10: =Dec!$J$24 -> 0 | N10: =SUM(B10:M10) -> 0
A11: PC Arrests | B11: =Jan!$K$24 -> 0 | C11: =Feb!$K$24 -> 0 | D11: =Mar!$K$24 -> 0 | E11: =Apr!$K$24 -> 0 | F11: =May!$K$24 -> 0 | G11: =Jun!$K$24 -> 0 | H11: =Jul!$K$24 -> 0 | I11: =Aug!$K$24 -> 0 | J11: =Sep!$K$24 -> 0 | K11: =Oct!$K$24 -> 0 | L11: =Nov!$K$24 -> 0 | M11: =Dec!$K$24 -> 0 | N11: =SUM(B11:M11) -> 0
A12: Agency Assist | B12: =Jan!$L$24 -> 0 | C12: =Feb!$L$24 -> 0 | D12: =Mar!$L$24 -> 0 | E12: =Apr!$L$24 -> 0 | F12: =May!$L$24 -> 0 | G12: =Jun!$L$24 -> 0 | H12: =Jul!$L$24 -> 0 | I12: =Aug!$L$24 -> 0 | J12: =Sep!$L$24 -> 0 | K12: =Oct!$L$24 -> 0 | L12: =Nov!$L$24 -> 0 | M12: =Dec!$L$24 -> 0 | N12: =SUM(B12:M12) -> 0
A14: Currency Seizures
A15: Month | B15: Jan. | C15: Feb. | D15: March | E15: April | F15: May | G15: June | H15: July | I15: Aug. | J15: Sept. | K15: Oct. | L15: Nov. | M15: Dec. | N15: TOTAL
A16: Seized | N16: =SUM(B16:M16) -> 0
A17: Awarded | N17: =SUM(B17:M17) -> 0
A19: End Of Year Uniform Detectives
A20: Month | B20: Jan. | C20: Feb. | D20: March | E20: April | F20: May | G20: June | H20: July | I20: Aug. | J20: Sept. | K20: Oct. | L20: Nov. | M20: Dec. | N20: TOTAL
A21: K9 Deploy | B21: =Jan!$D$55 -> 0 | C21: =Feb!$D$55 -> 0 | D21: =Mar!$D$55 -> 0 | E21: =Apr!$D$55 -> 0 | F21: =May!$D$55 -> 0 | G21: =Jun!$D$55 -> 0 | H21: =Jul!$D$55 -> 0 | I21: =Aug!$D$55 -> 0 | J21: =Sep!$D$55 -> 0 | K21: =Oct!$D$55 -> 0 | L21: =Nov!$D$55 -> 0 | M21: =Dec!$D$55 -> 0 | N21: =SUM(B21:M21) -> 0
A22: TNO Cases | B22: =Jan!$E$55 -> 0 | C22: =Feb!$E$55 -> 0 | D22: =Mar!$E$55 -> 0 | E22: =Apr!$E$55 -> 0 | F22: =May!$E$55 -> 0 | G22: =Jun!$E$55 -> 0 | H22: =Jul!$E$55 -> 0 | I22: =Aug!$E$55 -> 0 | J22: =Sep!$E$55 -> 0 | K22: =Oct!$E$55 -> 0 | L22: =Nov!$E$55 -> 0 | M22: =Dec!$E$55 -> 0 | N22: =SUM(B22:M22) -> 0
A23: Training Hours | B23: =Jan!$F$55 -> 0 | C23: =Feb!$F$55 -> 0 | D23: =Mar!$F$55 -> 0 | E23: =Apr!$F$55 -> 0 | F23: =May!$F$55 -> 0 | G23: =Jun!$F$55 -> 0 | H23: =Jul!$F$55 -> 0 | I23: =Aug!$F$55 -> 0 | J23: =Sep!$F$55 -> 0 | K23: =Oct!$F$55 -> 0 | L23: =Nov!$F$55 -> 0 | M23: =Dec!$F$55 -> 0 | N23: =SUM(B23:M23) -> 0
A24: Surv. Hours | B24: =Jan!$G$55 -> 0 | C24: =Feb!$G$55 -> 0 | D24: =Mar!$G$55 -> 0 | E24: =Apr!$G$55 -> 0 | F24: =May!$G$55 -> 0 | G24: =Jun!$G$55 -> 0 | H24: =Jul!$G$55 -> 0 | I24: =Aug!$G$55 -> 0 | J24: =Sep!$G$55 -> 0 | K24: =Oct!$G$55 -> 0 | L24: =Nov!$G$55 -> 0 | M24: =Dec!$G$55 -> 0 | N24: =SUM(B24:M24) -> 0
A25: Patrol/Jail Cases | B25: =Jan!$H$55 -> 0 | C25: =Feb!$H$55 -> 0 | D25: =Mar!$H$55 -> 0 | E25: =Apr!$H$55 -> 0 | F25: =May!$H$55 -> 0 | G25: =Jun!$H$55 -> 0 | H25: =Jul!$H$55 -> 0 | I25: =Aug!$H$55 -> 0 | J25: =Sep!$H$55 -> 0 | K25: =Oct!$H$55 -> 0 | L25: =Nov!$H$55 -> 0 | M25: =Dec!$H$55 -> 0 | N25: =SUM(B25:M25) -> 0
A26: Traffic Stops | B26: =Jan!$I$55 -> 0 | C26: =Feb!$I$55 -> 0 | D26: =Mar!$I$55 -> 0 | E26: =Apr!$I$55 -> 0 | F26: =May!$I$55 -> 0 | G26: =Jun!$I$55 -> 0 | H26: =Jul!$I$55 -> 0 | I26: =Aug!$I$55 -> 0 | J26: =Sep!$I$55 -> 0 | K26: =Oct!$I$55 -> 0 | L26: =Nov!$I$55 -> 0 | M26: =Dec!$I$55 -> 0 | N26: =SUM(B26:M26) -> 0
A27: Warrant Arrests | B27: =Jan!$J$55 -> 0 | C27: =Feb!$J$55 -> 0 | D27: =Mar!$J$55 -> 0 | E27: =Apr!$J$55 -> 0 | F27: =May!$J$55 -> 0 | G27: =Jun!$J$55 -> 0 | H27: =Jul!$J$55 -> 0 | I27: =Aug!$J$55 -> 0 | J27: =Sep!$J$55 -> 0 | K27: =Oct!$J$55 -> 0 | L27: =Nov!$J$55 -> 0 | M27: =Dec!$J$55 -> 0 | N27: =SUM(B27:M27) -> 0
A28: Agency Assist | B28: =Jan!$K$55 -> 0 | C28: =Feb!$K$55 -> 0 | D28: =Mar!$K$55 -> 0 | E28: =Apr!$K$55 -> 0 | F28: =May!$K$55 -> 0 | G28: =Jun!$K$55 -> 0 | H28: =Jul!$K$55 -> 0 | I28: =Aug!$K$55 -> 0 | J28: =Sep!$K$55 -> 0 | K28: =Oct!$K$55 -> 0 | L28: =Nov!$K$55 -> 0 | M28: =Dec!$K$55 -> 0 | N28: =SUM(B28:M28) -> 0
A29: Supp. reports | B29: =Jan!$L$55 -> 0 | C29: =Feb!$L$55 -> 0 | D29: =Mar!$L$55 -> 0 | E29: =Apr!$L$55 -> 0 | F29: =May!$L$55 -> 0 | G29: =Jun!$L$55 -> 0 | H29: =Jul!$L$55 -> 0 | I29: =Aug!$L$55 -> 0 | J29: =Sep!$L$55 -> 0 | K29: =Oct!$L$55 -> 0 | L29: =Nov!$L$55 -> 0 | M29: =Dec!$L$55 -> 0 | N29: =SUM(B29:M29) -> 0
A30: Drug Seizures
A31: Month | B31: Jan. | C31: Feb. | D31: March | E31: April | F31: May | G31: June | H31: July | I31: Aug. | J31: Sept. | K31: Oct. | L31: Nov. | M31: Dec. | N31: TOTAL
A32: Methamphetamine (g) | B32: =Jan!$N$52 -> 0 | C32: =Feb!$N$52 -> 0 | D32: =Mar!$N$52 -> 0 | E32: =Apr!$N$52 -> 0 | F32: =May!$N$52 -> 0 | G32: =Jun!$N$52 -> 0 | H32: =Jul!$N$52 -> 0 | I32: =Aug!$N$52 -> 0 | J32: =Sep!$N$52 -> 0 | K32: =Oct!$N$52 -> 0 | L32: =Nov!$N$52 -> 0 | M32: =Dec!$N$52 -> 0 | N32: =SUM(B32:M32) -> 0
A33: Cocaine (g) | B33: =Jan!$O$31 -> 0 | C33: =Feb!$O$31 -> 0 | D33: =Mar!$O$31 -> 0 | E33: =Apr!$O$31 -> 0 | F33: =May!$O$31 -> 0 | G33: =Jun!$O$31 -> 0 | H33: =Jul!$O$31 -> 0 | I33: =Aug!$O$31 -> 0 | J33: =Sep!$O$31 -> 0 | K33: =Oct!$O$31 -> 0 | L33: =Nov!$O$31 -> 0 | M33: =Dec!$O$31 -> 0 | N33: =SUM(B33:M33) -> 0
A34: Heroin (g) | B34: =Jan!$P$52 -> 0 | C34: =Feb!$P$52 -> 0 | D34: =Mar!$P$52 -> 0 | E34: =Apr!$P$52 -> 0 | F34: =May!$P$52 -> 0 | G34: =Jun!$P$52 -> 0 | H34: =Jul!$P$52 -> 0 | I34: =Aug!$P$52 -> 0 | J34: =Sep!$P$52 -> 0 | K34: =Oct!$P$52 -> 0 | L34: =Nov!$P$52 -> 0 | M34: =Dec!$P$52 -> 0 | N34: =SUM(B34:M34) -> 0
A35: Fentanyl (g) | B35: =Jan!$Q$52 -> 0 | C35: =Feb!$Q$52 -> 0 | D35: =Mar!$Q$52 -> 0 | E35: =Apr!$Q$52 -> 0 | F35: =May!$Q$52 -> 0 | G35: =Jun!$Q$52 -> 0 | H35: =Jul!$Q$52 -> 0 | I35: =Aug!$Q$52 -> 0 | J35: =Sep!$Q$52 -> 0 | K35: =Oct!$Q$52 -> 0 | L35: =Nov!$Q$52 -> 0 | M35: =Dec!$Q$52 -> 0 | N35: =SUM(B35:M35) -> 0
A36: Marijuana (OZ) | B36: =Jan!$R$52 -> 0 | C36: =Feb!$R$52 -> 0 | D36: =Mar!$R$52 -> 0 | E36: =Apr!$R$52 -> 0 | F36: =May!$R$52 -> 0 | G36: =Jun!$R$52 -> 0 | H36: =Jul!$R$52 -> 0 | I36: =Aug!$R$52 -> 0 | J36: =Sep!$R$52 -> 0 | K36: =Oct!$R$52 -> 0 | L36: =Nov!$R$52 -> 0 | M36: =Dec!$R$52 -> 0 | N36: =SUM(B36:M36) -> 0
A37: Promethazine/ Codeine (OZ) | B37: =Jan!$S$52 -> 0 | C37: =Feb!$S$52 -> 0 | D37: =Mar!$S$52 -> 0 | E37: =Apr!$S$52 -> 0 | F37: =May!$S$52 -> 0 | G37: =Jun!$S$52 -> 0 | H37: =Jul!$S$52 -> 0 | I37: =Aug!$S$52 -> 0 | J37: =Sep!$S$52 -> 0 | K37: =Oct!$S$52 -> 0 | L37: =Nov!$S$52 -> 0 | M37: =Dec!$S$52 -> 0 | N37: =SUM(B37:M37) -> 0
A38: RX Pills (#) | B38: =Jan!$T$52 -> 0 | C38: =Feb!$T$52 -> 0 | D38: =Mar!$T$52 -> 0 | E38: =Apr!$T$52 -> 0 | F38: =May!$T$52 -> 0 | G38: =Jun!$T$52 -> 0 | H38: =Jul!$T$52 -> 0 | I38: =Aug!$T$52 -> 0 | J38: =Sep!$T$52 -> 0 | K38: =Oct!$T$52 -> 0 | L38: =Nov!$T$52 -> 0 | M38: =Dec!$T$52 -> 0 | N38: =SUM(B38:M38) -> 0
